Workbook

Sheet JS工具總表
A1: 編號 | B1: 大類 | C1: 工具名稱 | D1: 功能說明 | E1: 可做出的效果／典型應用 | F1: 難度 | G1: Claude 單檔友善度 | H1: 搭配框架 | I1: 授權 | J1: GitHub 星數 | K1: 最後更新 | L1: 官網 | M1: 範例／Demo | N1: GitHub／原始碼 | O1: 網址檢查 | P1: 備註
A2: 1 | B2: 01 2D 繪圖與創意程式 | C2: p5.js | D2: Processing 的 JavaScript 版，用 setup()／draw() 迴圈逐格繪圖 | E2: 生成藝術、互動動畫、故事動畫、教學範例 | F2: 入門 | G2: ★★★ | H2: 原生 JS | I2: LGPL-2.1 | J2: 24070 | K2: 2026-09-30 | L2: https://p5js.org | M2: https://p5js.org/examples/ | N2: https://github.com/processing/p5.js | O2: 正常
A3: 2 | B3: 01 2D 繪圖與創意程式 | C3: q5.js | D3: 相容 p5.js 語法的輕量高速版，支援 WebGPU 渲染 | E3: 需要更高效能的 p5 作品、大量圖形 | F3: 入門 | G3: ★★★ | H3: 原生 JS | I3: LGPL-3.0 | J3: 422 | K3: 2026-09-27 | L3: https://q5js.org | M3: https://q5js.org/learn/ | N3: https://github.com/q5js/q5.js | O3: 正常
A4: 3 | B4: 01 2D 繪圖與創意程式 | C4: Paper.js | D4: 向量圖形腳本框架，擅長貝茲曲線與路徑布林運算 | E4: 向量插畫、路徑變形、互動海報 | F4: 中階 | G4: ★★★ | H4: 原生 JS | I4: MIT | J4: 15079 | K4: 2024-07-23 | L4: http://paperjs.org | M4: http://paperjs.org/examples/ | N4: https://github.com/paperjs/paper.js | O4: 正常
A5: 4 | B5: 01 2D 繪圖與創意程式 | C5: Two.js | D5: 同一套 API 輸出 SVG、Canvas、WebGL 的 2D 繪圖 | E5: 扁平風動畫、資訊圖動態 | F5: 入門 | G5: ★★★ | H5: 原生 JS | I5: MIT | J5: 8662 | K5: 2026-09-29 | L5: https://two.js.org | M5: https://two.js.org/examples/ | N5: https://github.com/jonobr1/two.js | O5: 正常
A6: 5 | B6: 01 2D 繪圖與創意程式 | C6: Konva.js | D6: Canvas 物件化框架，內建拖曳、事件、圖層 | E6: 線上設計器、貼圖編輯、互動白板 | F6: 中階 | G6: ★★★ | H6: 原生 JS／React／Vue | I6: MIT | J6: 14839 | K6: 2026-09-23 | L6: https://konvajs.org | M6: https://konvajs.org/docs/sandbox/ | N6: https://github.com/konvajs/konva | O6: 正常
A7: 6 | B7: 01 2D 繪圖與創意程式 | C7: Fabric.js | D7: Canvas 物件模型，支援選取、縮放、旋轉與 SVG 匯入匯出 | E7: 海報編輯器、T 恤設計、圖片標註 | F7: 中階 | G7: ★★★ | H7: 原生 JS | I7: MIT | J7: 31465 | K7: 2026-09-29 | L7: https://fabricjs.com | M7: https://fabricjs.com/demos/ | N7: https://github.com/fabricjs/fabric.js | O7: 正常
A8: 7 | B8: 01 2D 繪圖與創意程式 | C8: PixiJS | D8: 高效能 WebGL／WebGPU 2D 渲染引擎 | E8: 大量精靈動畫、2D 遊戲、互動廣告 | F8: 中階 | G8: ★★★ | H8: 原生 JS | I8: MIT | J8: 48246 | K8: 2026-09-30 | L8: https://pixijs.com | M8: https://pixijs.com/8.x/examples | N8: https://github.com/pixijs/pixijs | O8: 正常
A9: 8 | B9: 01 2D 繪圖與創意程式 | C9: EaselJS（CreateJS） | D9: 類 Flash 顯示清單的 Canvas 函式庫 | E9: Flash 風互動課件、小遊戲 | F9: 入門 | G9: ★★★ | H9: 原生 JS | I9: MIT | J9: 8159 | K9: 2026-01-24 | L9: https://createjs.com/easeljs | M9: https://createjs.com/demos | N9: https://github.com/CreateJS/EaselJS | O9: 正常
A10: 9 | B10: 01 2D 繪圖與創意程式 | C10: Rough.js | D10: 手繪草圖風格的線條與圖形 | E10: 手繪風圖表、白板風說明圖 | F10: 入門 | G10: ★★★ | H10: 原生 JS | I10: MIT | J10: 21218 | K10: 2024-07-28 | L10: https://roughjs.com | M10: https://roughjs.com | N10: https://github.com/rough-stuff/rough | O10: 正常
A11: 10 | B11: 01 2D 繪圖與創意程式 | C11: Zdog | D11: 偽 3D 扁平向量引擎，程式碼極短 | E11: 可愛扁平 3D 角色、旋轉圖示 | F11: 入門 | G11: ★★★ | H11: 原生 JS | I11: MIT | J11: 10663 | K11: 2023-07-18 | L11: https://zzz.dog | M11: https://zzz.dog/getting-started | N11: https://github.com/metafizzy/zdog | O11: 正常
A12: 11 | B12: 01 2D 繪圖與創意程式 | C12: SVG.js | D12: 輕量 SVG 建立、操作與動畫 | E12: 向量圖示動畫、互動圖解 | F12: 入門 | G12: ★★★ | H12: 原生 JS | I12: MIT | J12: 11826 | K12: 2026-08-04 | L12: https://svgjs.dev | M12: https://svgjs.dev/docs/3.2/ | N12: https://github.com/svgdotjs/svg.js | O12: 正常
A13: 12 | B13: 01 2D 繪圖與創意程式 | C13: Snap.svg | D13: Adobe 出品的 SVG 操作函式庫 | E13: SVG 動畫、互動插圖 | F13: 入門 | G13: ★★★ | H13: 原生 JS | I13: Apache-2.0 | J13: 14005 | K13: 2026-06-12 | L13: http://snapsvg.io | M13: http://snapsvg.io/demos/ | N13: https://github.com/adobe-webplatform/Snap.svg | O13: 正常
... A33: 32 | B33: 02 3D 引擎與 WebGL／WebGPU | C33: Spline | D33: 3D 設計工具，可匯出網頁嵌入碼與 runtime | E33: 無程式 3D 互動主視覺 | F33: 入門 | G33: ★★ | H33: 原生 JS／React | I33: MIT | J33: 1421 | K33: 2026-03-13 | L33: https://spline.design | M33: https://community.spline.design | N33: https://github.com/splinetool/react-spline | O33: 正常
A34: 33 | B34: 02 3D 引擎與 WebGL／WebGPU | C34: Needle Engine | D34: 把 Unity／Blender 場景匯出成網頁 3D 的引擎 | E34: 3D 互動網站、WebXR | F34: 中階 | G34: ★ | H34: 原生 JS／編輯器 | I34: 商用授權（有免費方案） | L34: https://needle.tools | M34: https://engine.needle.tools/samples/ | O34: 正常
A35: 34 | B35: 02 3D 引擎與 WebGL／WebGPU | C35: Shader Park | D35: 用 JS 語法寫 SDF 程序化 3D shader | E35: 程序化 3D 雕塑、音訊反應造型 | F35: 中階 | G35: ★★★ | H35: 原生 JS | I35: MIT | J35: 824 | K35: 2024-05-28 | L35: https://shaderpark.com | M35: https://shaderpark.com/explore | N35: https://github.com/shader-park/shader-park-core | O35: 正常
A36: 35 | B36: 02 3D 引擎與 WebGL／WebGPU | C36: glslCanvas | D36: 在網頁 canvas 執行 GLSL 片段 shader | E36: 展示 GLSL 特效、動態背景 | F36: 中階 | G36: ★★★ | H36: 原生 JS | I36: MIT | J36: 2276 | K36: 2023-07-19 | L36: https://github.com/patriciogonzalezvivo/glslCanvas | M36: https://thebookofshaders.com | N36: https://github.com/patriciogonzalezvivo/glslCanvas | O36: 正常
A37: 36 | B37: 02 3D 引擎與 WebGL／WebGPU | C37: curtains.js | D37: 把 DOM 圖片、影片轉成 WebGL 平面加特效 | E37: 圖片扭曲 hover、轉場 | F37: 中階 | G37: ★★★ | H37: 原生 JS | I37: MIT | J37: 1827 | K37: 2025-04-03 | L37: https://www.curtainsjs.com | M37: https://www.curtainsjs.com/examples/multiple-planes-scroll-effect/index.html | N37: https://github.com/martinlaxenaire/curtainsjs | O37: 正常
A38: 37 | B38: 02 3D 引擎與 WebGL／WebGPU | C38: GPU.js | D38: 用 JavaScript 寫 GPU 平行運算 | E38: 大量粒子計算、影像處理加速 | F38: 進階 | G38: ★★★ | H38: 原生 JS | I38: MIT | J38: 15479 | K38: 2026-09-29 | L38: https://gpu.rocks | M38: https://gpu.rocks | N38: https://github.com/gpujs/gpu.js | O38: 正常
A39: 38 | B39: 02 3D 引擎與 WebGL／WebGPU | C39: three-vrm | D39: Three.js 載入 VRM 虛擬人偶模型 | E39: VTuber 角色、虛擬主播 | F39: 中階 | G39: ★★★ | H39: 原生 JS | I39: MIT | J39: 2192 | K39: 2026-09-30 | L39: https://github.com/pixiv/three-vrm | M39: https://pixiv.github.io/three-vrm/packages/three-vrm/examples/basic.html | N39: https://github.com/pixiv/three-vrm | O39: 正常
A40: 39 | B40: 02 3D 引擎與 WebGL／WebGPU | C40: pixi-live2d-display | D40: 在 PixiJS 顯示 Live2D 模型 | E40: Live2D 看板娘、互動角色 | F40: 中階 | G40: ★★ | H40: 原生 JS | I40: MIT | J40: 1503 | K40: 2024-08-20 | L40: https://github.com/guansss/pixi-live2d-display | M40: https://guansss.github.io/pixi-live2d-display/ | N40: https://github.com/guansss/pixi-live2d-display | O40: 正常
A41: 40 | B41: 02 3D 引擎與 WebGL／WebGPU | C41: Cesium（CesiumJS） | D41: 3D 地球與地理空間引擎 | E41: 3D 城市、飛行模擬、衛星軌道 | F41: 中階 | G41: ★★ | H41: 原生 JS | I41: Apache-2.0 | J41: 15787 | K41: 2026-09-30 | L41: https://cesium.com/platform/cesiumjs/ | M41: https://sandcastle.cesium.com | N41: https://github.com/CesiumGS/cesium | O41: 正常
A42: 41 | B42: 03 3D 外掛與調參工具 | C42: postprocessing | D42: Three.js 後製特效（泛光、景深、色差、雜訊） | E42: 電影感 3D 畫面 | F42: 中階 | G42: ★★★ | H42: 原生 JS | I42: Zlib | J42: 2871 | K42: 2026-09-27 | L42: https://github.com/pmndrs/postprocessing | M42: https://pmndrs.github.io/postprocessing/public/demo/ | N42: https://github.com/pmndrs/postprocessing | O42: 正常
A43: 42 | B43: 03 3D 外掛與調參工具 | C43: Theatre.js | D43: 可視化時間軸動畫編輯器，可調 Three.js 動畫與運鏡 | E43: 3D 過場動畫、網站運鏡 | F43: 中階 | G43: ★★ | H43: 原生 JS／React | I43: Apache-2.0 | J43: 12715 | K43: 2024-08-14 | L43: https://www.theatrejs.com | M43: https://www.theatrejs.com/docs/latest | N43: https://github.com/theatre-js/theatre | O43: 正常
A44: 43 | B44: 03 3D 外掛與調參工具 | C44: lil-gui | D44: 輕量參數調整面板 | E44: 即時調色、調動畫參數 | F44: 入門 | G44: ★★★ | H44: 原生 JS | I44: MIT | J44: 1642 | K44: 2025-10-12 | L44: https://lil-gui.georgealways.com | M44: https://lil-gui.georgealways.com | N44: https://github.com/georgealways/lil-gui | O44: 正常
A45: 44 | B45: 03 3D 外掛與調參工具 | C45: Tweakpane | D45: 精美參數面板，可監看數值曲線 | E45: 生成藝術調參、Demo 控制台 | F45: 入門 | G45: ★★★ | H45: 原生 JS | I45: MIT | J45: 4599 | K45: 2026-03-15 | L45: https://tweakpane.github.io/docs/ | M45: https://tweakpane.github.io/docs/ | N45: https://github.com/cocopon/tweakpane | O45: 正常
A46: 45 | B46: 03 3D 外掛與調參工具 | C46: troika-three-text | D46: Three.js 高品質 SDF 文字渲染 | E46: 3D 標題、VR 介面文字 | F46: 中階 | G46: ★★★ | H46: 原生 JS | I46: MIT | J46: 1975 | K46: 2026-07-24 | L46: https://protectwise.github.io/troika/troika-three-text/ | M46: https://protectwise.github.io/troika/troika-three-text/ | N46: https://github.com/protectwise/troika | O46: 正常
... A58: 57 | B58: 04 動畫補間與動態設計 | C58: AutoAnimate | D58: 一行程式讓清單增刪排序自動有動畫 | E58: 待辦清單、排序動畫 | F58: 入門 | G58: ★★★ | H58: 原生 JS／React／Vue | I58: MIT | J58: 13925 | K58: 2026-07-10 | L58: https://auto-animate.formkit.com | M58: https://auto-animate.formkit.com | N58: https://github.com/formkit/auto-animate | O58: 正常
A59: 58 | B59: 04 動畫補間與動態設計 | C59: Animate.css | D59: 現成 CSS 動畫類別庫 | E59: 進場、彈跳、抖動效果 | F59: 入門 | G59: ★★★ | H59: CSS | I59: Hippocratic-2.1 | J59: 82842 | K59: 2024-07-29 | L59: https://animate.style | M59: https://animate.style | N59: https://github.com/animate-css/animate.css | O59: 正常 | P59: Hippocratic 授權：含使用倫理限制條款
A60: 59 | B60: 04 動畫補間與動態設計 | C60: Barba.js | D60: 無刷新換頁的頁面轉場 | E60: 作品集網站流暢轉場 | F60: 中階 | G60: ★★★ | H60: 原生 JS | I60: MIT | J60: 12987 | K60: 2024-12-02 | L60: https://barba.js.org | M60: https://barba.js.org/docs/getstarted/intro/ | N60: https://github.com/barbajs/barba | O60: 正常
A61: 60 | B61: 04 動畫補間與動態設計 | C61: Swup | D61: 多頁網站頁面轉場 | E61: 部落格、形象站轉場 | F61: 中階 | G61: ★★★ | H61: 原生 JS | I61: MIT | J61: 5233 | K61: 2026-09-29 | L61: https://swup.js.org | M61: https://swup.js.org/getting-started/demos/ | N61: https://github.com/swup/swup | O61: 正常
A62: 61 | B62: 04 動畫補間與動態設計 | C62: KUTE.js | D62: 高效能補間，含 SVG 形狀變形 | E62: SVG morph、色彩補間 | F62: 中階 | G62: ★★★ | H62: 原生 JS | I62: MIT | J62: 2643 | K62: 2026-03-26 | L62: https://thednp.github.io/kute.js/ | M62: https://thednp.github.io/kute.js/ | N62: https://github.com/thednp/kute.js | O62: 正常
A63: 62 | B63: 04 動畫補間與動態設計 | C63: Scene.js | D63: 關鍵影格時間軸動畫 | E63: CSS 關鍵影格、媒體同步 | F63: 中階 | G63: ★★★ | H63: 原生 JS | I63: MIT | J63: 2771 | K63: 2023-06-19 | L63: https://daybrush.com/scenejs/ | M63: https://daybrush.com/scenejs/ | N63: https://github.com/daybrush/scenejs | O63: 正常
A64: 63 | B64: 04 動畫補間與動態設計 | C64: Vivus | D64: 讓 SVG 線條「一筆一筆描出來」 | E64: Logo 描繪、簽名動畫 | F64: 入門 | G64: ★★★ | H64: 原生 JS | I64: MIT | J64: 15485 | K64: 2022-07-06 | L64: https://maxwellito.github.io/vivus/ | M64: https://maxwellito.github.io/vivus/ | N64: https://github.com/maxwellito/vivus | O64: 正常
A65: 64 | B65: 05 捲動、視差與輪播 | C65: ScrollTrigger（GSAP 外掛） | D65: 捲動觸發與捲動綁定動畫 | E65: 捲動敘事、釘選區段、橫向捲動 | F65: 中階 | G65: ★★★ | H65: 原生 JS | I65: GSAP 標準授權（免費含商用） | J65: 28739 | K65: 2026-04-13 | L65: https://gsap.com/docs/v3/Plugins/ScrollTrigger/ | M65: https://gsap.com/scroll/ | N65: https://github.com/greensock/GSAP | O65: 正常
A66: 65 | B66: 05 捲動、視差與輪播 | C66: Lenis | D66: 平滑捲動 | E66: 高級感網站捲動手感 | F66: 入門 | G66: ★★★ | H66: 原生 JS | I66: MIT | J66: 16094 | K66: 2026-09-22 | L66: https://lenis.dev | M66: https://lenis.dev | N66: https://github.com/darkroomengineering/lenis | O66: 正常
A67: 66 | B67: 05 捲動、視差與輪播 | C67: Locomotive Scroll | D67: 平滑捲動加視差偵測 | E67: 視差作品集 | F67: 中階 | G67: ★★★ | H67: 原生 JS | I67: MIT | J67: 8866 | K67: 2026-06-30 | L67: https://scroll.locomotive.ca | M67: https://scroll.locomotive.ca | N67: https://github.com/locomotivemtl/locomotive-scroll | O67: 正常
A68: 67 | B68: 05 捲動、視差與輪播 | C68: ScrollMagic | D68: 經典捲動互動框架 | E68: 捲動動畫場景 | F68: 中階 | G68: ★★★ | H68: 原生 JS | I68: MIT | J68: 14958 | K68: 2026-09-25 | L68: https://scrollmagic.io | M68: https://scrollmagic.io/examples/ | N68: https://github.com/janpaepke/ScrollMagic | O68: 正常
A69: 68 | B69: 05 捲動、視差與輪播 | C69: AOS（Animate On Scroll） | D69: 捲動進場動畫，用 HTML 屬性設定 | E69: 區塊淡入、滑入 | F69: 入門 | G69: ★★★ | H69: 原生 JS | I69: MIT | J69: 28062 | K69: 2024-03-26 | L69: https://michalsnik.github.io/aos/ | M69: https://michalsnik.github.io/aos/ | N69: https://github.com/michalsnik/aos | O69: 正常
A70: 69 | B70: 05 捲動、視差與輪播 | C70: ScrollReveal | D70: 捲動顯示動畫 | E70: 區塊逐一出現 | F70: 入門 | G70: ★ | H70: 原生 JS | I70: GPL-3.0 | J70: 22476 | K70: 2024-04-05 | L70: https://scrollrevealjs.org | M70: https://scrollrevealjs.org | N70: https://github.com/jlmakes/scrollreveal | O70: 正常 | P70: GPL／AGPL 授權：開源專案可免費用，閉源商用需購買商業授權
...

Sheet 分類統計
A1: 大類 | B1: 工具數 | C1: ★★★ 數（單檔 HTML 可跑） | D1: 入門難度數 | E1: ★★★ 比例
A2: 01 2D 繪圖與創意程式 | B2: =COUNTIF(JS工具總表!$B$2:$B$329,A2) -> 18 | C2: =COUNTIFS(JS工具總表!$B$2:$B$329,A2,JS工具總表!$G$2:$G$329,"★★★") -> 17 | D2: =COUNTIFS(JS工具總表!$B$2:$B$329,A2,JS工具總表!$F$2:$F$329,"入門") -> 10 | E2: =IF(B2=0,0,C2/B2) -> 0.94444444
A3: 02 3D 引擎與 WebGL／WebGPU | B3: =COUNTIF(JS工具總表!$B$2:$B$329,A3) -> 22 | C3: =COUNTIFS(JS工具總表!$B$2:$B$329,A3,JS工具總表!$G$2:$G$329,"★★★") -> 12 | D3: =COUNTIFS(JS工具總表!$B$2:$B$329,A3,JS工具總表!$F$2:$F$329,"入門") -> 3 | E3: =IF(B3=0,0,C3/B3) -> 0.54545455
A4: 03 3D 外掛與調參工具 | B4: =COUNTIF(JS工具總表!$B$2:$B$329,A4) -> 7 | C4: =COUNTIFS(JS工具總表!$B$2:$B$329,A4,JS工具總表!$G$2:$G$329,"★★★") -> 5 | D4: =COUNTIFS(JS工具總表!$B$2:$B$329,A4,JS工具總表!$F$2:$F$329,"入門") -> 3 | E4: =IF(B4=0,0,C4/B4) -> 0.71428571
A5: 04 動畫補間與動態設計 | B5: =COUNTIF(JS工具總表!$B$2:$B$329,A5) -> 16 | C5: =COUNTIFS(JS工具總表!$B$2:$B$329,A5,JS工具總表!$G$2:$G$329,"★★★") -> 14 | D5: =COUNTIFS(JS工具總表!$B$2:$B$329,A5,JS工具總表!$F$2:$F$329,"入門") -> 9 | E5: =IF(B5=0,0,C5/B5) -> 0.875
A6: 05 捲動、視差與輪播 | B6: =COUNTIF(JS工具總表!$B$2:$B$329,A6) -> 16 | C6: =COUNTIFS(JS工具總表!$B$2:$B$329,A6,JS工具總表!$G$2:$G$329,"★★★") -> 13 | D6: =COUNTIFS(JS工具總表!$B$2:$B$329,A6,JS工具總表!$F$2:$F$329,"入門") -> 11 | E6: =IF(B6=0,0,C6/B6) -> 0.8125
A7: 06 文字特效與排版 | B7: =COUNTIF(JS工具總表!$B$2:$B$329,A7) -> 11 | C7: =COUNTIFS(JS工具總表!$B$2:$B$329,A7,JS工具總表!$G$2:$G$329,"★★★") -> 10 | D7: =COUNTIFS(JS工具總表!$B$2:$B$329,A7,JS工具總表!$F$2:$F$329,"入門") -> 9 | E7: =IF(B7=0,0,C7/B7) -> 0.90909091
A8: 07 粒子與背景特效 | B8: =COUNTIF(JS工具總表!$B$2:$B$329,A8) -> 14 | C8: =COUNTIFS(JS工具總表!$B$2:$B$329,A8,JS工具總表!$G$2:$G$329,"★★★") -> 13 | D8: =COUNTIFS(JS工具總表!$B$2:$B$329,A8,JS工具總表!$F$2:$F$329,"入門") -> 13 | E8: =IF(B8=0,0,C8/B8) -> 0.92857143
A9: 08 物理引擎 | B9: =COUNTIF(JS工具總表!$B$2:$B$329,A9) -> 8 | C9: =COUNTIFS(JS工具總表!$B$2:$B$329,A9,JS工具總表!$G$2:$G$329,"★★★") -> 8 | D9: =COUNTIFS(JS工具總表!$B$2:$B$329,A9,JS工具總表!$F$2:$F$329,"入門") -> 1 | E9: =IF(B9=0,0,C9/B9) -> 1
A10: 09 遊戲引擎與遊戲工具 | B10: =COUNTIF(JS工具總表!$B$2:$B$329,A10) -> 14 | C10: =COUNTIFS(JS工具總表!$B$2:$B$329,A10,JS工具總表!$G$2:$G$329,"★★★") -> 10 | D10: =COUNTIFS(JS工具總表!$B$2:$B$329,A10,JS工具總表!$F$2:$F$329,"入門") -> 7 | E10: =IF(B10=0,0,C10/B10) -> 0.71428571
A11: 10 資料視覺化圖表與表格 | B11: =COUNTIF(JS工具總表!$B$2:$B$329,A11) -> 26 | C11: =COUNTIFS(JS工具總表!$B$2:$B$329,A11,JS工具總表!$G$2:$G$329,"★★★") -> 20 | D11: =COUNTIFS(JS工具總表!$B$2:$B$329,A11,JS工具總表!$F$2:$F$329,"入門") -> 21 | E11: =IF(B11=0,0,C11/B11) -> 0.76923077
A12: 11 網路圖與關係圖 | B12: =COUNTIF(JS工具總表!$B$2:$B$329,A12) -> 7 | C12: =COUNTIFS(JS工具總表!$B$2:$B$329,A12,JS工具總表!$G$2:$G$329,"★★★") -> 6 | D12: =COUNTIFS(JS工具總表!$B$2:$B$329,A12,JS工具總表!$F$2:$F$329,"入門") -> 4 | E12: =IF(B12=0,0,C12/B12) -> 0.85714286
A13: 12 流程圖、心智圖、白板與行事曆 | B13: =COUNTIF(JS工具總表!$B$2:$B$329,A13) -> 17 | C13: =COUNTIFS(JS工具總表!$B$2:$B$329,A13,JS工具總表!$G$2:$G$329,"★★★") -> 12 | D13: =COUNTIFS(JS工具總表!$B$2:$B$329,A13,JS工具總表!$F$2:$F$329,"入門") -> 10 | E13: =IF(B13=0,0,C13/B13) -> 0.70588235
... A28: 27 硬體與實體互動 | B28: =COUNTIF(JS工具總表!$B$2:$B$329,A28) -> 2 | C28: =COUNTIFS(JS工具總表!$B$2:$B$329,A28,JS工具總表!$G$2:$G$329,"★★★") -> 1 | D28: =COUNTIFS(JS工具總表!$B$2:$B$329,A28,JS工具總表!$F$2:$F$329,"入門") -> 1 | E28: =IF(B28=0,0,C28/B28) -> 0.5
A29: 合計 | B29: =SUM(B2:B28) -> 328 | C29: =SUM(C2:C28) -> 260 | D29: =SUM(D2:D28) -> 184 | E29: =IF(B29=0,0,C29/B29) -> 0.79268293
A30: 核對：總表列數 | B30: =COUNTA(JS工具總表!$C$2:$C$329) -> 328

Sheet 範例靈感平台
A1: 編號 | B1: 平台 | C1: 說明 | D1: 適合找的範例 | E1: 網址 | F1: 網址檢查
A2: 1 | B2: OpenProcessing | C2: p5.js 作品社群，可直接看原始碼並 fork | D2: 生成藝術、p5 動畫 | E2: https://openprocessing.org | F2: 正常
A3: 2 | B3: p5.js Web Editor | C3: 官方線上編輯器，貼上程式即可執行，ml5 官方範例也放這裡 | D3: p5.js、ml5.js | E3: https://editor.p5js.org | F3: 正常
A4: 3 | B4: The Coding Train | C4: Daniel Shiffman 的 p5.js 影片教學與挑戰題 | D4: p5.js、ml5.js 入門 | E4: https://thecodingtrain.com | F4: 正常
A5: 4 | B5: CodePen | C5: 前端特效最大社群，搜尋工具名稱即可找到範例 | D5: CSS、GSAP、Three.js 等 | E5: https://codepen.io | F5: 正常（瀏覽器確認）
A6: 5 | B6: Shadertoy | C6: GLSL shader 作品庫，可即時修改 | D6: shader、光影、分形 | E6: https://www.shadertoy.com | F6: 需人工確認（Cloudflare 驗證）
A7: 6 | B7: The Book of Shaders | C7: 互動式 GLSL 入門書，範例可直接編輯 | D7: shader 入門 | E7: https://thebookofshaders.com | F7: 正常
A8: 7 | B8: GLSL Sandbox | C8: 片段 shader 作品集 | D8: shader 背景 | E8: https://glslsandbox.com | F8: 正常
A9: 8 | B9: Three.js Journey | C9: Three.js 系統課程，課程作品展示 | D9: Three.js | E9: https://threejs-journey.com | F9: 正常
A10: 9 | B10: three.js 論壇 Showcase | C10: 社群分享的 Three.js 作品 | D10: Three.js | E10: https://discourse.threejs.org/c/showcase/7 | F10: 正常
A11: 10 | B11: Codrops | C11: 創意前端教學與 Demo（WebGL、捲動、文字特效） | D11: GSAP、Three.js、WebGL | E11: https://tympanus.net/codrops/ | F11: 正常
A12: 11 | B12: Awwwards | C12: 得獎網站設計集，可看頂尖動效網站 | D12: 網站動效靈感 | E12: https://www.awwwards.com | F12: 正常
A13: 12 | B13: Experiments with Google | C13: Google 創意實驗集（AI、WebGL、AR） | D13: TF.js、MediaPipe、WebXR | E13: https://experiments.withgoogle.com | F13: 正常
... A21: 20 | B21: LottieFiles | C21: Lottie 動畫素材庫與播放器 | D21: Lottie 動畫 | E21: https://lottiefiles.com | F21: 正常（瀏覽器確認）

Sheet 組合配方
A1: 編號 | B1: 工具組合 | C1: 可做出的成品 | D1: 給 Claude 的提示詞範例 | E1: 參考範例網址
A2: 1 | B2: p5.js ＋ ml5.js | C2: 手勢互動藝術 | D2: 用 p5.js 加 ml5.js 的 handPose 做單檔 HTML：開啟鏡頭，食指指尖畫出彩色光軌，張開手掌就清空畫面。 | E2: https://editor.p5js.org/ml5/sketches
A3: 2 | B3: p5.js ＋ p5.sound | C3: 麥克風聲音視覺化 | D3: 用 p5.js 與 p5.sound 做單檔 HTML：讀取麥克風，畫出隨音量與頻譜脈動的圓形頻譜圖。 | E3: https://p5js.org/examples/
A4: 3 | B4: p5.js ＋ Mediabunny | C4: p5 動畫匯出 MP4 | D4: 寫一支 20 秒 p5.js 動畫，加一個按鈕，用 Mediabunny 把 canvas 逐格編碼成 MP4 下載。 | E4: https://mediabunny.dev
A5: 4 | B5: Matter.js ＋ p5.js | C5: 物理掉落互動 | D5: 用 Matter.js 加 p5.js：把「歡迎光臨」每個字變成物理方塊，從上方掉落堆疊，可用滑鼠拖曳丟擲。 | E5: https://brm.io/matter-js/demo/
A6: 5 | B6: Three.js ＋ GSAP ScrollTrigger | C6: 捲動 3D 產品頁 | D6: 用 Three.js 加 GSAP ScrollTrigger 做一頁式網站：捲動時 3D 模型旋轉、鏡頭推近，每一段顯示一段文案。 | E6: https://gsap.com/scroll/
A7: 6 | B7: Three.js ＋ cannon-es | C7: 3D 物理擲骰 | D7: 用 Three.js 加 cannon-es 做可以擲出的 3D 骰子，骰子停下後在畫面顯示點數。 | E7: https://pmndrs.github.io/cannon-es/
A8: 7 | B8: Three.js ＋ Tone.js | C8: 音樂驅動 3D 視覺 | D8: 用 Tone.js 播放一段合成器旋律，Three.js 場景裡的球體依每個音符的音高與力度變形、變色。 | E8: https://tonejs.github.io/examples/
A9: 8 | B9: MediaPipe ＋ Three.js | C9: 臉部追蹤 AR 濾鏡 | D9: 用 MediaPipe Face Landmarker 追蹤臉部，Three.js 在眼睛位置疊一副 3D 眼鏡，跟著頭轉動。 | E9: https://developers.google.com/edge/mediapipe/solutions/vision/face_landmarker
A10: 9 | B10: A-Frame ＋ MindAR | C10: 海報或名片 AR | D10: 用 A-Frame 加 MindAR 做圖片追蹤 AR：手機鏡頭對準名片，名片上方浮出 3D 標誌與介紹文字。 | E10: https://hiukim.github.io/mind-ar-js-doc/examples/summary
A11: 10 | B11: Vanta.js ＋ Typed.js ＋ AOS | C11: 動態形象首頁 | D11: 做一個形象首頁：Vanta.js 動態背景、Typed.js 打出標語、下方區塊用 AOS 捲動淡入。 | E11: https://www.vantajs.com
A12: 11 | B12: Lenis ＋ GSAP ＋ SplitType | C12: 高級感文字動效網站 | D12: 用 Lenis 平滑捲動，搭配 GSAP 與 SplitType 讓每段標題逐字往上浮現。 | E12: https://lenis.dev
A13: 12 | B13: Phaser ＋ ZzFX | C13: 2D 小遊戲含音效 | D13: 用 Phaser 做單檔 HTML 橫向跳躍遊戲：方向鍵移動、空白鍵跳、吃金幣加分，音效用 ZzFX 產生。 | E13: https://killedbyapixel.github.io/ZzFX/
... A23: 22 | B23: Remotion ＋ Lottie | C23: 程式化產生影片 | D23: 用 Remotion 做 15 秒 1080x1920 直式影片：Lottie 動畫開場，接著三張數據卡片依序進場，輸出 MP4。 | E23: https://www.remotion.dev/showcase

Sheet 說明
A1: 項目 | B1: 說明
A2: 用途 | B2: 整理可搭配 Claude 產生網頁作品的 JavaScript 工具，依功能分 27 大類，共 328 個工具。
A3: 工作表 | B3: JS工具總表：主清單，可用篩選器依大類、難度、友善度篩選。分類統計：各大類工具數（公式自動計算）。範例靈感平台：找範例與素材的網站。組合配方：多工具搭配的成品與提示詞範例。
A4: 難度 | B4: 入門：看範例改參數就能用。中階：需理解該工具的核心概念。進階：需要圖學、數學或底層 API 知識。屬主觀分級。
A5: Claude 單檔友善度 | B5: ★★★：一個 HTML 檔加 CDN 即可執行，最適合直接請 Claude 產出。★★：需要 npm 建置或特定框架（React、Vue 等）。★：需要 API 金鑰、帳號、付費或商業授權、或後端伺服器。
A6: 授權 | B6: 優先採用 GitHub 偵測結果，偵測失敗時讀取 package.json 或 LICENSE 檔判斷，商業授權類手動標註。僅供參考，商用前請以官方授權條款為準。
A7: GitHub 星數與最後更新 | B7: 2026-10-01 透過 GitHub API 取得。最後更新為倉庫最後一次 push 的日期。
A8: 網址檢查 | B8: 2026-10-01 以程式逐一請求 540 個官網與範例網址（HTTP 200 視為正常）。被機器人防護擋下（403）的網址改用瀏覽器開啟確認，標為「正常（瀏覽器確認）」。有 Cloudflare 驗證頁、無法自動確認的網址標為「需人工確認」。GitHub 網址以 API 確認倉庫存在。
A9: 檢查限制 | B9: 網址檢查只確認頁面能開啟，未逐頁確認範例內容仍在。功能說明依整理當下的知識撰寫，未逐一實際執行每個工具驗證。部分「範例」連結為內含可執行範例的文件頁。
A10: GitHub 已封存 | B10: 標註於備註欄。已封存的工具仍可使用，但不會再修正問題，新專案建議優先選擇仍在維護的替代品。
A11: API 金鑰安全 | B11: 需要金鑰的服務（Claude API、Google Maps、Mapbox 等），金鑰不可直接寫進公開網頁，需透過後端轉發。
A12: 整理日期 | B12: 2026-10-01
